{
 "cells": [
  {
   "cell_type": "code",
   "execution_count": 1,
   "id": "bc12c2bc-bdff-418c-ac07-4b8db179cc28",
   "metadata": {},
   "outputs": [],
   "source": [
    "import numpy as np\n",
    "import matplotlib.pyplot as plt\n",
    "plt.rcParams[\"figure.dpi\"] = 120\n",
    "import numba\n",
    "\n",
    "import tensorflow.keras as keras\n",
    "from tensorflow.keras import Model\n",
    "from tensorflow.keras import Sequential\n",
    "from tensorflow.keras.layers import Conv2D\n",
    "from tensorflow.keras import optimizers\n",
    "\n",
    "from IPython.display import clear_output"
   ]
  },
  {
   "cell_type": "code",
   "execution_count": 2,
   "id": "29e4c02e-123a-4c1b-820b-24d0ec587ec7",
   "metadata": {},
   "outputs": [],
   "source": [
    "def genTrainingImages(imgSize, N, minCircles=1, maxCircles=4, minRadius=125, maxRadius=200, overlap=False, noise=1):\n",
    "    img = np.zeros((N, *imgSize))\n",
    "    numCircles = np.random.randint(minCircles, maxCircles, size=N)\n",
    "    \n",
    "    circleCentersX = np.random.randint(0, imgSize[0], size=N)\n",
    "    circleCentersY = np.random.randint(0, imgSize[1], size=N)\n",
    "    \n",
    "    Y = np.arange(imgSize[0]).reshape((imgSize[0], 1)) # Column vector\n",
    "    X = np.arange(imgSize[1]).reshape((1, imgSize[1])) # Row vector\n",
    "    \n",
    "    # Generate the circles\n",
    "    for i in range(N):\n",
    "        radii = np.random.uniform(minRadius, maxRadius, size=numCircles[i])\n",
    "        j = 0\n",
    "        while j < numCircles[i]:\n",
    "            yC, xC = np.random.randint(0, imgSize[0]), np.random.randint(0, imgSize[1])\n",
    "            newCircle = ((X - xC)**2 + (Y - yC)**2) < radii[j]**2\n",
    "            # Make sure circles don't overlap\n",
    "            if np.max(img[i] + newCircle) == 1:\n",
    "                img[i] += newCircle\n",
    "                j += 1\n",
    "                \n",
    "    # Now add noise\n",
    "    noisyImg = img + np.random.uniform(0.01*noise, noise, size=img.shape)\n",
    "    \n",
    "    return noisyImg, img"
   ]
  },
  {
   "cell_type": "code",
   "execution_count": null,
   "id": "4c38b6b8-2c61-4b97-a148-46cb80435b54",
   "metadata": {},
   "outputs": [],
   "source": [
    "noisyImg, img = genTrainingImages((1024, 1280), 100, noise=10)\n",
    "\n",
    "fig, ax = plt.subplots(1, 2, figsize=(8,4))\n",
    "\n",
    "ax[0].imshow(img[0])\n",
    "ax[1].imshow(noisyImg[0])\n",
    "plt.show()"
   ]
  },
  {
   "cell_type": "code",
   "execution_count": 4,
   "id": "81003634-b1b2-4b72-9f9e-2089f101a2da",
   "metadata": {},
   "outputs": [],
   "source": [
    "# Set up the neural network\n",
    "network = Sequential()\n",
    "\n",
    "# 5x5 kernel size, 10 channels in first hidden layer:\n",
    "network.add(Conv2D(5, 5, input_shape=(None,None,1),\n",
    "               activation=\"relu\", padding='same'))\n",
    "\n",
    "# 5x5 kernel size, 10 channels\n",
    "network.add(Conv2D(10, 5, activation=\"relu\", padding='same'))\n",
    "# 5x5 kernel size, 5 channels\n",
    "network.add(Conv2D(5, 5, activation=\"relu\", padding='same'))\n",
    "# 5x5 kernel size, 5 channels\n",
    "network.add(Conv2D(5, 5, activation=\"relu\", padding='same'))\n",
    "\n",
    "# 5x5 kernel size, only 1 channel in last hidden layer:\n",
    "network.add(Conv2D(1, 5, activation=\"sigmoid\", padding='same'))\n",
    "\n",
    "network.compile(loss='mean_squared_error', optimizer='adam')"
   ]
  },
  {
   "cell_type": "code",
   "execution_count": null,
   "id": "13031f91-c957-4f0d-97d6-dd789887ba84",
   "metadata": {},
   "outputs": [
    {
     "name": "stdout",
     "output_type": "stream",
     "text": [
      "ERROR! Session/line number was not unique in database. History logging moved to new session 4332\n"
     ]
    },
    {
     "name": "stderr",
     "output_type": "stream",
     "text": [
      "ERROR:root:Internal Python error in the inspect module.\n",
      "Below is the traceback from this internal error.\n",
      "\n",
      "ERROR:root:Internal Python error in the inspect module.\n",
      "Below is the traceback from this internal error.\n",
      "\n",
      "ERROR:root:Internal Python error in the inspect module.\n",
      "Below is the traceback from this internal error.\n",
      "\n"
     ]
    },
    {
     "name": "stdout",
     "output_type": "stream",
     "text": [
      "Traceback (most recent call last):\n",
      "  File \"/home/jack/miniconda3/envs/py37/lib/python3.7/site-packages/IPython/core/interactiveshell.py\", line 3444, in run_code\n",
      "    exec(code_obj, self.user_global_ns, self.user_ns)\n",
      "  File \"/tmp/ipykernel_68086/3243078105.py\", line 9, in <module>\n",
      "    costArr[i] = network.train_on_batch(noisyImg[:-1], img[:-1])\n",
      "  File \"/home/jack/miniconda3/envs/py37/lib/python3.7/site-packages/tensorflow_core/python/keras/engine/training.py\", line 1078, in train_on_batch\n",
      "    standalone=True)\n",
      "  File \"/home/jack/miniconda3/envs/py37/lib/python3.7/site-packages/tensorflow_core/python/keras/engine/training_v2_utils.py\", line 416, in train_on_batch\n",
      "    extract_tensors_from_dataset=True)\n",
      "  File \"/home/jack/miniconda3/envs/py37/lib/python3.7/site-packages/tensorflow_core/python/keras/engine/training.py\", line 2383, in _standardize_user_data\n",
      "    batch_size=batch_size)\n",
      "  File \"/home/jack/miniconda3/envs/py37/lib/python3.7/site-packages/tensorflow_core/python/keras/engine/training.py\", line 2410, in _standardize_tensors\n",
      "    exception_prefix='input')\n",
      "  File \"/home/jack/miniconda3/envs/py37/lib/python3.7/site-packages/tensorflow_core/python/keras/engine/training_utils.py\", line 573, in standardize_input_data\n",
      "    'with shape ' + str(data_shape))\n",
      "ValueError: Error when checking input: expected conv2d_5_input to have 4 dimensions, but got array with shape (100, 512, 640)\n",
      "\n",
      "During handling of the above exception, another exception occurred:\n",
      "\n",
      "Traceback (most recent call last):\n",
      "  File \"/home/jack/miniconda3/envs/py37/lib/python3.7/site-packages/IPython/core/interactiveshell.py\", line 2064, in showtraceback\n",
      "    stb = value._render_traceback_()\n",
      "AttributeError: 'ValueError' object has no attribute '_render_traceback_'\n",
      "\n",
      "During handling of the above exception, another exception occurred:\n",
      "\n",
      "Traceback (most recent call last):\n",
      "  File \"/home/jack/miniconda3/envs/py37/lib/python3.7/site-packages/IPython/core/ultratb.py\", line 1101, in get_records\n",
      "    return _fixed_getinnerframes(etb, number_of_lines_of_context, tb_offset)\n",
      "  File \"/home/jack/miniconda3/envs/py37/lib/python3.7/site-packages/IPython/core/ultratb.py\", line 248, in wrapped\n",
      "    return f(*args, **kwargs)\n",
      "  File \"/home/jack/miniconda3/envs/py37/lib/python3.7/site-packages/IPython/core/ultratb.py\", line 281, in _fixed_getinnerframes\n",
      "    records = fix_frame_records_filenames(inspect.getinnerframes(etb, context))\n",
      "  File \"/home/jack/miniconda3/envs/py37/lib/python3.7/inspect.py\", line 1502, in getinnerframes\n",
      "    frameinfo = (tb.tb_frame,) + getframeinfo(tb, context)\n",
      "  File \"/home/jack/miniconda3/envs/py37/lib/python3.7/inspect.py\", line 1460, in getframeinfo\n",
      "    filename = getsourcefile(frame) or getfile(frame)\n",
      "  File \"/home/jack/miniconda3/envs/py37/lib/python3.7/inspect.py\", line 696, in getsourcefile\n",
      "    if getattr(getmodule(object, filename), '__loader__', None) is not None:\n",
      "  File \"/home/jack/miniconda3/envs/py37/lib/python3.7/inspect.py\", line 733, in getmodule\n",
      "    if ismodule(module) and hasattr(module, '__file__'):\n",
      "  File \"/home/jack/miniconda3/envs/py37/lib/python3.7/site-packages/tensorflow/__init__.py\", line 50, in __getattr__\n",
      "    module = self._load()\n",
      "  File \"/home/jack/miniconda3/envs/py37/lib/python3.7/site-packages/tensorflow/__init__.py\", line 44, in _load\n",
      "    module = _importlib.import_module(self.__name__)\n",
      "  File \"/home/jack/miniconda3/envs/py37/lib/python3.7/importlib/__init__.py\", line 127, in import_module\n",
      "    return _bootstrap._gcd_import(name[level:], package, level)\n",
      "  File \"<frozen importlib._bootstrap>\", line 1006, in _gcd_import\n",
      "  File \"<frozen importlib._bootstrap>\", line 983, in _find_and_load\n",
      "  File \"<frozen importlib._bootstrap>\", line 965, in _find_and_load_unlocked\n",
      "ModuleNotFoundError: No module named 'tensorflow_core.estimator'\n",
      "Traceback (most recent call last):\n",
      "  File \"/home/jack/miniconda3/envs/py37/lib/python3.7/site-packages/IPython/core/interactiveshell.py\", line 3444, in run_code\n",
      "    exec(code_obj, self.user_global_ns, self.user_ns)\n",
      "  File \"/tmp/ipykernel_68086/3243078105.py\", line 9, in <module>\n",
      "    costArr[i] = network.train_on_batch(noisyImg[:-1], img[:-1])\n",
      "  File \"/home/jack/miniconda3/envs/py37/lib/python3.7/site-packages/tensorflow_core/python/keras/engine/training.py\", line 1078, in train_on_batch\n",
      "    standalone=True)\n",
      "  File \"/home/jack/miniconda3/envs/py37/lib/python3.7/site-packages/tensorflow_core/python/keras/engine/training_v2_utils.py\", line 416, in train_on_batch\n",
      "    extract_tensors_from_dataset=True)\n",
      "  File \"/home/jack/miniconda3/envs/py37/lib/python3.7/site-packages/tensorflow_core/python/keras/engine/training.py\", line 2383, in _standardize_user_data\n",
      "    batch_size=batch_size)\n",
      "  File \"/home/jack/miniconda3/envs/py37/lib/python3.7/site-packages/tensorflow_core/python/keras/engine/training.py\", line 2410, in _standardize_tensors\n",
      "    exception_prefix='input')\n",
      "  File \"/home/jack/miniconda3/envs/py37/lib/python3.7/site-packages/tensorflow_core/python/keras/engine/training_utils.py\", line 573, in standardize_input_data\n",
      "    'with shape ' + str(data_shape))\n",
      "ValueError: Error when checking input: expected conv2d_5_input to have 4 dimensions, but got array with shape (100, 512, 640)\n",
      "\n",
      "During handling of the above exception, another exception occurred:\n",
      "\n",
      "Traceback (most recent call last):\n",
      "  File \"/home/jack/miniconda3/envs/py37/lib/python3.7/site-packages/IPython/core/interactiveshell.py\", line 2064, in showtraceback\n",
      "    stb = value._render_traceback_()\n",
      "AttributeError: 'ValueError' object has no attribute '_render_traceback_'\n",
      "\n",
      "During handling of the above exception, another exception occurred:\n",
      "\n",
      "Traceback (most recent call last):\n",
      "  File \"/home/jack/miniconda3/envs/py37/lib/python3.7/site-packages/IPython/core/interactiveshell.py\", line 3364, in run_ast_nodes\n",
      "    if (await self.run_code(code, result,  async_=asy)):\n",
      "  File \"/home/jack/miniconda3/envs/py37/lib/python3.7/site-packages/IPython/core/interactiveshell.py\", line 3461, in run_code\n",
      "    self.showtraceback(running_compiled_code=True)\n",
      "  File \"/home/jack/miniconda3/envs/py37/lib/python3.7/site-packages/IPython/core/interactiveshell.py\", line 2067, in showtraceback\n",
      "    value, tb, tb_offset=tb_offset)\n",
      "  File \"/home/jack/miniconda3/envs/py37/lib/python3.7/site-packages/IPython/core/ultratb.py\", line 1368, in structured_traceback\n",
      "    self, etype, value, tb, tb_offset, number_of_lines_of_context)\n",
      "  File \"/home/jack/miniconda3/envs/py37/lib/python3.7/site-packages/IPython/core/ultratb.py\", line 1268, in structured_traceback\n",
      "    self, etype, value, tb, tb_offset, number_of_lines_of_context\n",
      "  File \"/home/jack/miniconda3/envs/py37/lib/python3.7/site-packages/IPython/core/ultratb.py\", line 1125, in structured_traceback\n",
      "    tb_offset)\n",
      "  File \"/home/jack/miniconda3/envs/py37/lib/python3.7/site-packages/IPython/core/ultratb.py\", line 1082, in format_exception_as_a_whole\n",
      "    last_unique, recursion_repeat = find_recursion(orig_etype, evalue, records)\n",
      "  File \"/home/jack/miniconda3/envs/py37/lib/python3.7/site-packages/IPython/core/ultratb.py\", line 382, in find_recursion\n",
      "    return len(records), 0\n",
      "TypeError: object of type 'NoneType' has no len()\n",
      "\n",
      "During handling of the above exception, another exception occurred:\n",
      "\n",
      "Traceback (most recent call last):\n",
      "  File \"/home/jack/miniconda3/envs/py37/lib/python3.7/site-packages/IPython/core/interactiveshell.py\", line 2064, in showtraceback\n",
      "    stb = value._render_traceback_()\n",
      "AttributeError: 'TypeError' object has no attribute '_render_traceback_'\n",
      "\n",
      "During handling of the above exception, another exception occurred:\n",
      "\n",
      "Traceback (most recent call last):\n",
      "  File \"/home/jack/miniconda3/envs/py37/lib/python3.7/site-packages/IPython/core/ultratb.py\", line 1101, in get_records\n",
      "    return _fixed_getinnerframes(etb, number_of_lines_of_context, tb_offset)\n",
      "  File \"/home/jack/miniconda3/envs/py37/lib/python3.7/site-packages/IPython/core/ultratb.py\", line 248, in wrapped\n",
      "    return f(*args, **kwargs)\n",
      "  File \"/home/jack/miniconda3/envs/py37/lib/python3.7/site-packages/IPython/core/ultratb.py\", line 281, in _fixed_getinnerframes\n",
      "    records = fix_frame_records_filenames(inspect.getinnerframes(etb, context))\n",
      "  File \"/home/jack/miniconda3/envs/py37/lib/python3.7/inspect.py\", line 1502, in getinnerframes\n",
      "    frameinfo = (tb.tb_frame,) + getframeinfo(tb, context)\n",
      "  File \"/home/jack/miniconda3/envs/py37/lib/python3.7/inspect.py\", line 1460, in getframeinfo\n",
      "    filename = getsourcefile(frame) or getfile(frame)\n",
      "  File \"/home/jack/miniconda3/envs/py37/lib/python3.7/inspect.py\", line 696, in getsourcefile\n",
      "    if getattr(getmodule(object, filename), '__loader__', None) is not None:\n",
      "  File \"/home/jack/miniconda3/envs/py37/lib/python3.7/inspect.py\", line 733, in getmodule\n",
      "    if ismodule(module) and hasattr(module, '__file__'):\n",
      "  File \"/home/jack/miniconda3/envs/py37/lib/python3.7/site-packages/tensorflow/__init__.py\", line 50, in __getattr__\n",
      "    module = self._load()\n",
      "  File \"/home/jack/miniconda3/envs/py37/lib/python3.7/site-packages/tensorflow/__init__.py\", line 44, in _load\n",
      "    module = _importlib.import_module(self.__name__)\n",
      "  File \"/home/jack/miniconda3/envs/py37/lib/python3.7/importlib/__init__.py\", line 127, in import_module\n",
      "    return _bootstrap._gcd_import(name[level:], package, level)\n",
      "  File \"<frozen importlib._bootstrap>\", line 1006, in _gcd_import\n",
      "  File \"<frozen importlib._bootstrap>\", line 983, in _find_and_load\n",
      "  File \"<frozen importlib._bootstrap>\", line 965, in _find_and_load_unlocked\n",
      "ModuleNotFoundError: No module named 'tensorflow_core.estimator'\n",
      "Traceback (most recent call last):\n",
      "  File \"/home/jack/miniconda3/envs/py37/lib/python3.7/site-packages/IPython/core/interactiveshell.py\", line 3444, in run_code\n",
      "    exec(code_obj, self.user_global_ns, self.user_ns)\n",
      "  File \"/tmp/ipykernel_68086/3243078105.py\", line 9, in <module>\n",
      "    costArr[i] = network.train_on_batch(noisyImg[:-1], img[:-1])\n",
      "  File \"/home/jack/miniconda3/envs/py37/lib/python3.7/site-packages/tensorflow_core/python/keras/engine/training.py\", line 1078, in train_on_batch\n",
      "    standalone=True)\n",
      "  File \"/home/jack/miniconda3/envs/py37/lib/python3.7/site-packages/tensorflow_core/python/keras/engine/training_v2_utils.py\", line 416, in train_on_batch\n",
      "    extract_tensors_from_dataset=True)\n",
      "  File \"/home/jack/miniconda3/envs/py37/lib/python3.7/site-packages/tensorflow_core/python/keras/engine/training.py\", line 2383, in _standardize_user_data\n",
      "    batch_size=batch_size)\n",
      "  File \"/home/jack/miniconda3/envs/py37/lib/python3.7/site-packages/tensorflow_core/python/keras/engine/training.py\", line 2410, in _standardize_tensors\n",
      "    exception_prefix='input')\n",
      "  File \"/home/jack/miniconda3/envs/py37/lib/python3.7/site-packages/tensorflow_core/python/keras/engine/training_utils.py\", line 573, in standardize_input_data\n",
      "    'with shape ' + str(data_shape))\n",
      "ValueError: Error when checking input: expected conv2d_5_input to have 4 dimensions, but got array with shape (100, 512, 640)\n",
      "\n",
      "During handling of the above exception, another exception occurred:\n",
      "\n",
      "Traceback (most recent call last):\n",
      "  File \"/home/jack/miniconda3/envs/py37/lib/python3.7/site-packages/IPython/core/interactiveshell.py\", line 2064, in showtraceback\n",
      "    stb = value._render_traceback_()\n",
      "AttributeError: 'ValueError' object has no attribute '_render_traceback_'\n",
      "\n",
      "During handling of the above exception, another exception occurred:\n",
      "\n",
      "Traceback (most recent call last):\n",
      "  File \"/home/jack/miniconda3/envs/py37/lib/python3.7/site-packages/IPython/core/interactiveshell.py\", line 3364, in run_ast_nodes\n",
      "    if (await self.run_code(code, result,  async_=asy)):\n",
      "  File \"/home/jack/miniconda3/envs/py37/lib/python3.7/site-packages/IPython/core/interactiveshell.py\", line 3461, in run_code\n",
      "    self.showtraceback(running_compiled_code=True)\n",
      "  File \"/home/jack/miniconda3/envs/py37/lib/python3.7/site-packages/IPython/core/interactiveshell.py\", line 2067, in showtraceback\n",
      "    value, tb, tb_offset=tb_offset)\n",
      "  File \"/home/jack/miniconda3/envs/py37/lib/python3.7/site-packages/IPython/core/ultratb.py\", line 1368, in structured_traceback\n",
      "    self, etype, value, tb, tb_offset, number_of_lines_of_context)\n",
      "  File \"/home/jack/miniconda3/envs/py37/lib/python3.7/site-packages/IPython/core/ultratb.py\", line 1268, in structured_traceback\n",
      "    self, etype, value, tb, tb_offset, number_of_lines_of_context\n",
      "  File \"/home/jack/miniconda3/envs/py37/lib/python3.7/site-packages/IPython/core/ultratb.py\", line 1125, in structured_traceback\n",
      "    tb_offset)\n",
      "  File \"/home/jack/miniconda3/envs/py37/lib/python3.7/site-packages/IPython/core/ultratb.py\", line 1082, in format_exception_as_a_whole\n",
      "    last_unique, recursion_repeat = find_recursion(orig_etype, evalue, records)\n",
      "  File \"/home/jack/miniconda3/envs/py37/lib/python3.7/site-packages/IPython/core/ultratb.py\", line 382, in find_recursion\n",
      "    return len(records), 0\n",
      "TypeError: object of type 'NoneType' has no len()\n",
      "\n",
      "During handling of the above exception, another exception occurred:\n",
      "\n",
      "Traceback (most recent call last):\n",
      "  File \"/home/jack/miniconda3/envs/py37/lib/python3.7/site-packages/IPython/core/interactiveshell.py\", line 2064, in showtraceback\n",
      "    stb = value._render_traceback_()\n",
      "AttributeError: 'TypeError' object has no attribute '_render_traceback_'\n",
      "\n",
      "During handling of the above exception, another exception occurred:\n",
      "\n",
      "Traceback (most recent call last):\n",
      "  File \"/home/jack/miniconda3/envs/py37/lib/python3.7/site-packages/IPython/core/interactiveshell.py\", line 2947, in _run_cell\n",
      "    return runner(coro)\n",
      "  File \"/home/jack/miniconda3/envs/py37/lib/python3.7/site-packages/IPython/core/async_helpers.py\", line 68, in _pseudo_sync_runner\n",
      "    coro.send(None)\n",
      "  File \"/home/jack/miniconda3/envs/py37/lib/python3.7/site-packages/IPython/core/interactiveshell.py\", line 3173, in run_cell_async\n",
      "    interactivity=interactivity, compiler=compiler, result=result)\n",
      "  File \"/home/jack/miniconda3/envs/py37/lib/python3.7/site-packages/IPython/core/interactiveshell.py\", line 3383, in run_ast_nodes\n",
      "    self.showtraceback()\n",
      "  File \"/home/jack/miniconda3/envs/py37/lib/python3.7/site-packages/IPython/core/interactiveshell.py\", line 2067, in showtraceback\n",
      "    value, tb, tb_offset=tb_offset)\n",
      "  File \"/home/jack/miniconda3/envs/py37/lib/python3.7/site-packages/IPython/core/ultratb.py\", line 1368, in structured_traceback\n",
      "    self, etype, value, tb, tb_offset, number_of_lines_of_context)\n",
      "  File \"/home/jack/miniconda3/envs/py37/lib/python3.7/site-packages/IPython/core/ultratb.py\", line 1268, in structured_traceback\n",
      "    self, etype, value, tb, tb_offset, number_of_lines_of_context\n",
      "  File \"/home/jack/miniconda3/envs/py37/lib/python3.7/site-packages/IPython/core/ultratb.py\", line 1143, in structured_traceback\n",
      "    chained_exceptions_tb_offset)\n",
      "  File \"/home/jack/miniconda3/envs/py37/lib/python3.7/site-packages/IPython/core/ultratb.py\", line 1082, in format_exception_as_a_whole\n",
      "    last_unique, recursion_repeat = find_recursion(orig_etype, evalue, records)\n",
      "  File \"/home/jack/miniconda3/envs/py37/lib/python3.7/site-packages/IPython/core/ultratb.py\", line 382, in find_recursion\n",
      "    return len(records), 0\n",
      "TypeError: object of type 'NoneType' has no len()\n",
      "\n",
      "During handling of the above exception, another exception occurred:\n",
      "\n",
      "Traceback (most recent call last):\n",
      "  File \"/home/jack/miniconda3/envs/py37/lib/python3.7/site-packages/IPython/core/interactiveshell.py\", line 2064, in showtraceback\n",
      "    stb = value._render_traceback_()\n",
      "AttributeError: 'TypeError' object has no attribute '_render_traceback_'\n",
      "\n",
      "During handling of the above exception, another exception occurred:\n",
      "\n",
      "Traceback (most recent call last):\n",
      "  File \"/home/jack/miniconda3/envs/py37/lib/python3.7/site-packages/IPython/core/ultratb.py\", line 1101, in get_records\n",
      "    return _fixed_getinnerframes(etb, number_of_lines_of_context, tb_offset)\n",
      "  File \"/home/jack/miniconda3/envs/py37/lib/python3.7/site-packages/IPython/core/ultratb.py\", line 248, in wrapped\n",
      "    return f(*args, **kwargs)\n",
      "  File \"/home/jack/miniconda3/envs/py37/lib/python3.7/site-packages/IPython/core/ultratb.py\", line 281, in _fixed_getinnerframes\n",
      "    records = fix_frame_records_filenames(inspect.getinnerframes(etb, context))\n",
      "  File \"/home/jack/miniconda3/envs/py37/lib/python3.7/inspect.py\", line 1502, in getinnerframes\n",
      "    frameinfo = (tb.tb_frame,) + getframeinfo(tb, context)\n",
      "  File \"/home/jack/miniconda3/envs/py37/lib/python3.7/inspect.py\", line 1460, in getframeinfo\n",
      "    filename = getsourcefile(frame) or getfile(frame)\n",
      "  File \"/home/jack/miniconda3/envs/py37/lib/python3.7/inspect.py\", line 696, in getsourcefile\n",
      "    if getattr(getmodule(object, filename), '__loader__', None) is not None:\n",
      "  File \"/home/jack/miniconda3/envs/py37/lib/python3.7/inspect.py\", line 733, in getmodule\n",
      "    if ismodule(module) and hasattr(module, '__file__'):\n",
      "  File \"/home/jack/miniconda3/envs/py37/lib/python3.7/site-packages/tensorflow/__init__.py\", line 50, in __getattr__\n",
      "    module = self._load()\n",
      "  File \"/home/jack/miniconda3/envs/py37/lib/python3.7/site-packages/tensorflow/__init__.py\", line 44, in _load\n",
      "    module = _importlib.import_module(self.__name__)\n",
      "  File \"/home/jack/miniconda3/envs/py37/lib/python3.7/importlib/__init__.py\", line 127, in import_module\n",
      "    return _bootstrap._gcd_import(name[level:], package, level)\n",
      "  File \"<frozen importlib._bootstrap>\", line 1006, in _gcd_import\n",
      "  File \"<frozen importlib._bootstrap>\", line 983, in _find_and_load\n",
      "  File \"<frozen importlib._bootstrap>\", line 965, in _find_and_load_unlocked\n",
      "ModuleNotFoundError: No module named 'tensorflow_core.estimator'\n"
     ]
    }
   ],
   "source": [
    "batchSize = 100\n",
    "epochs = 100\n",
    "\n",
    "costArr = np.zeros(epochs)\n",
    "\n",
    "for i in range(epochs):\n",
    "    noisyImg, img = genTrainingImages((512, 640), batchSize+1, noise=5, minRadius=30, maxRadius=60)\n",
    "    \n",
    "    costArr[i] = network.train_on_batch(noisyImg[:-1], img[:-1])\n",
    "    \n",
    "    clear_output(wait=True)\n",
    "    fig, ax = plt.subplots(1, 4, figsize=(15,5))\n",
    "    \n",
    "    ax[0].plot(costArr[:i+1])\n",
    "    ax[0].set_ylabel('Cost')\n",
    "    ax[0].set_xlabel('Epoch')\n",
    "    ax[0].set_yscale('log')\n",
    "    \n",
    "    ax[1].imshow(img[-1])\n",
    "    ax[1].set_title('Validation image')\n",
    "    \n",
    "    ax[2].imshow(noisyImg[-1])\n",
    "    ax[2].set_title('Input image')\n",
    "\n",
    "    ax[3].imshow(network.predict(noisyImg[-1,:,:,None])[:,:,0,0])\n",
    "    ax[3].set_title('Network prediction')\n",
    "    \n",
    "    fig.tight_layout()\n",
    "    plt.show()"
   ]
  },
  {
   "cell_type": "code",
   "execution_count": null,
   "id": "3b651c0d-4519-4007-9a7a-c06a52cd04c8",
   "metadata": {},
   "outputs": [],
   "source": []
  },
  {
   "cell_type": "code",
   "execution_count": null,
   "id": "09cbc5e7-8867-43ca-a2a2-944dbead8aa0",
   "metadata": {},
   "outputs": [],
   "source": []
  }
 ],
 "metadata": {
  "kernelspec": {
   "display_name": "Python 3 (ipykernel)",
   "language": "python",
   "name": "python3"
  },
  "language_info": {
   "codemirror_mode": {
    "name": "ipython",
    "version": 3
   },
   "file_extension": ".py",
   "mimetype": "text/x-python",
   "name": "python",
   "nbconvert_exporter": "python",
   "pygments_lexer": "ipython3",
   "version": "3.7.11"
  }
 },
 "nbformat": 4,
 "nbformat_minor": 5
}
